<?xml version="1.0"?>
<robot xmlns:xacro="http://www.ros.org/wiki/xacro" name="ur10_with_gripper">
    <xacro:arg name="initial_positions_file" default="$(find moveit_ur10)/config/initial_positions.yaml" />
    <xacro:arg name="ros2_control_hardware_type" default="isaac" />

    <!-- Create world link -->
    <link name="world"/>
    
    <!-- links -  main serial chain -->
    <link name="base_link"/>
    <link name="base_link_inertia">
        <visual>
            <origin rpy="0 0 3.141592653589793" xyz="0 0 0"/>
            <geometry>
                <mesh filename="package://ur_description/meshes/ur10/visual/base.dae"/>
            </geometry>
        </visual>
        <collision>
            <origin rpy="0 0 3.141592653589793" xyz="0 0 0"/>
            <geometry>
                <mesh filename="package://ur_description/meshes/ur10/collision/base.stl"/>
            </geometry>
        </collision>
        <inertial>
            <mass value="4.0"/>
            <origin rpy="0 0 0" xyz="0 0 0"/>
            <inertia ixx="0.0061063308908" ixy="0.0" ixz="0.0" iyy="0.0061063308908" iyz="0.0" izz="0.01125"/>
        </inertial>
    </link>
    <link name="shoulder_link">
        <visual>
            <origin rpy="0 0 3.141592653589793" xyz="0 0 0"/>
            <geometry>
                <mesh filename="package://ur_description/meshes/ur10/visual/shoulder.dae"/>
            </geometry>
        </visual>
        <collision>
            <origin rpy="0 0 3.141592653589793" xyz="0 0 0"/>
            <geometry>
                <mesh filename="package://ur_description/meshes/ur10/collision/shoulder.stl"/>
            </geometry>
        </collision>
        <inertial>
            <mass value="7.1"/>
            <origin rpy="1.570796326794897 0 0" xyz="0.021 -0.027 0.0"/>
            <inertia ixx="0.03408" ixy="2e-05" ixz="-0.00425" iyy="0.03529" iyz="8e-05" izz="0.02156"/>
        </inertial>
    </link>
    <link name="upper_arm_link">
        <visual>
            <origin rpy="1.5707963267948966 0 -1.5707963267948966" xyz="0 0 0.220941"/>
            <geometry>
                <mesh filename="package://ur_description/meshes/ur10/visual/upperarm.dae"/>
            </geometry>
        </visual>
        <collision>
            <origin rpy="1.5707963267948966 0 -1.5707963267948966" xyz="0 0 0.220941"/>
            <geometry>
                <mesh filename="package://ur_description/meshes/ur10/collision/upperarm.stl"/>
            </geometry>
        </collision>
        <inertial>
            <mass value="12.7"/>
            <origin rpy="0 0 0" xyz="-0.232 0.0 0.158"/>
            <inertia ixx="0.02814" ixy="5e-05" ixz="-0.01561" iyy="0.77068" iyz="2e-05" izz="0.76943"/>
        </inertial>
    </link>
    <link name="forearm_link">
        <visual>
            <origin rpy="1.5707963267948966 0 -1.5707963267948966" xyz="0 0 0.049042"/>
            <geometry>
                <mesh filename="package://ur_description/meshes/ur10/visual/forearm.dae"/>
            </geometry>
        </visual>
        <collision>
            <origin rpy="1.5707963267948966 0 -1.5707963267948966" xyz="0 0 0.049042"/>
            <geometry>
                <mesh filename="package://ur_description/meshes/ur10/collision/forearm.stl"/>
            </geometry>
        </collision>
        <inertial>
            <mass value="4.27"/>
            <origin rpy="0 0 0" xyz="-0.3323 0.0 0.068"/>
            <inertia ixx="0.01014" ixy="8e-05" ixz="0.00916" iyy="0.30928" iyz="0.0" izz="0.30646"/>
        </inertial>
    </link>
    <link name="wrist_1_link">
        <visual>
            <origin rpy="1.5707963267948966 0 0" xyz="0 0 -0.1149"/>
            <geometry>
                <mesh filename="package://ur_description/meshes/ur10/visual/wrist1.dae"/>
            </geometry>
        </visual>
        <collision>
            <origin rpy="1.5707963267948966 0 0" xyz="0 0 -0.1149"/>
            <geometry>
                <mesh filename="package://ur_description/meshes/ur10/collision/wrist1.stl"/>
            </geometry>
        </collision>
        <inertial>
            <mass value="2.0"/>
            <origin rpy="1.570796326794897 0 0" xyz="0.0 -0.018 0.007"/>
            <inertia ixx="0.00296" ixy="-1e-05" ixz="0.0" iyy="0.00222" iyz="-0.00024" izz="0.00258"/>
        </inertial>
    </link>
    <link name="wrist_2_link">
        <visual>
            <origin rpy="0 0 0" xyz="0 0 -0.1158"/>
            <geometry>
                <mesh filename="package://ur_description/meshes/ur10/visual/wrist2.dae"/>
            </geometry>
        </visual>
        <collision>
            <origin rpy="0 0 0" xyz="0 0 -0.1158"/>
            <geometry>
                <mesh filename="package://ur_description/meshes/ur10/collision/wrist2.stl"/>
            </geometry>
        </collision>
        <inertial>
            <mass value="2.0"/>
            <origin rpy="-1.570796326794897 0 0" xyz="0.0 0.018 -0.007"/>
            <inertia ixx="0.00296" ixy="-1e-05" ixz="0.0" iyy="0.00222" iyz="-0.00024" izz="0.00258"/>
        </inertial>
    </link>
    <link name="wrist_3_link">
        <visual>
            <origin rpy="1.5707963267948966 0 0" xyz="0 0 -0.0922"/>
            <geometry>
                <mesh filename="package://ur_description/meshes/ur10/visual/wrist3.dae"/>
            </geometry>
        </visual>
        <collision>
            <origin rpy="1.5707963267948966 0 0" xyz="0 0 -0.0922"/>
            <geometry>
                <mesh filename="package://ur_description/meshes/ur10/collision/wrist3.stl"/>
            </geometry>
        </collision>
        <inertial>
            <mass value="0.365"/>
            <origin rpy="0 0 0" xyz="0.0 0 -0.026"/>
            <inertia ixx="0.0004" ixy="0.0" ixz="0.0" iyy="0.00041" iyz="0.0" izz="0.00034"/>
        </inertial>
    </link>
    
    <!-- base_joint fixes base_link to the environment -->
    <joint name="base_joint" type="fixed">
        <origin rpy="0 0 0" xyz="0 0 0"/>
        <parent link="world"/>
        <child link="base_link"/>
    </joint>
    
    <!-- joints - main serial chain -->
    <joint name="base_link-base_link_inertia" type="fixed">
        <parent link="base_link"/>
        <child link="base_link_inertia"/>
        <origin rpy="0 0 3.141592653589793" xyz="0 0 0"/>
    </joint>
    <joint name="shoulder_pan_joint" type="revolute">
        <parent link="base_link_inertia"/>
        <child link="shoulder_link"/>
        <origin rpy="0 0 0" xyz="0 0 0.1273"/>
        <axis xyz="0 0 1"/>
        <limit effort="330.0" lower="-6.283185307179586" upper="6.283185307179586" velocity="2.0943951023931953"/>
        <dynamics damping="0" friction="0"/>
    </joint>
    <joint name="shoulder_lift_joint" type="revolute">
        <parent link="shoulder_link"/>
        <child link="upper_arm_link"/>
        <origin rpy="1.570796327 0 0" xyz="0 0 0"/>
        <axis xyz="0 0 1"/>
        <limit effort="330.0" lower="-6.283185307179586" upper="6.283185307179586" velocity="2.0943951023931953"/>
        <dynamics damping="0" friction="0"/>
    </joint>
    <joint name="elbow_joint" type="revolute">
        <parent link="upper_arm_link"/>
        <child link="forearm_link"/>
        <origin rpy="0 0 0" xyz="-0.612 0 0"/>
        <axis xyz="0 0 1"/>
        <limit effort="150.0" lower="-3.141592653589793" upper="3.141592653589793" velocity="3.141592653589793"/>
        <dynamics damping="0" friction="0"/>
    </joint>
    <joint name="wrist_1_joint" type="revolute">
        <parent link="forearm_link"/>
        <child link="wrist_1_link"/>
        <origin rpy="0 0 0" xyz="-0.5723 0 0.163941"/>
        <axis xyz="0 0 1"/>
        <limit effort="56.0" lower="-6.283185307179586" upper="6.283185307179586" velocity="3.141592653589793"/>
        <dynamics damping="0" friction="0"/>
    </joint>
    <joint name="wrist_2_joint" type="revolute">
        <parent link="wrist_1_link"/>
        <child link="wrist_2_link"/>
        <origin rpy="1.570796327 0 0" xyz="0 -0.1157 -2.373046667922381e-11"/>
        <axis xyz="0 0 1"/>
        <limit effort="56.0" lower="-6.283185307179586" upper="6.283185307179586" velocity="3.141592653589793"/>
        <dynamics damping="0" friction="0"/>
    </joint>
    <joint name="wrist_3_joint" type="revolute">
        <parent link="wrist_2_link"/>
        <child link="wrist_3_link"/>
        <origin rpy="1.570796326589793 3.141592653589793 3.141592653589793" xyz="0 0.0922 -1.891053610911353e-11"/>
        <axis xyz="0 0 1"/>
        <limit effort="56.0" lower="-6.283185307179586" upper="6.283185307179586" velocity="3.141592653589793"/>
        <dynamics damping="0" friction="0"/>
    </joint>
    
    <!-- ROS-Industrial 'flange' frame - attachment point for EEF models -->
    <link name="flange"/>
    <joint name="wrist_3-flange" type="fixed">
        <parent link="wrist_3_link"/>
        <child link="flange"/>
        <origin rpy="0 -1.5707963267948966 -1.5707963267948966" xyz="0 0 0"/>
    </joint>
    
    <!-- ROS-Industrial 'tool0' frame - all-zeros tool frame -->
    <link name="tool0"/>
    <joint name="flange-tool0" type="fixed">
        <origin rpy="1.5707963267948966 0 1.5707963267948966" xyz="0 0 0"/>
        <parent link="flange"/>
        <child link="tool0"/>
    </joint>
    
    <!-- Base link of the gripper -->
    <link name="gripper_base">
        <visual>
            <origin rpy="0 0 0" xyz="0 0 0.05"/>
            <geometry>
                <cylinder length="0.1" radius="0.03"/>
            </geometry>
            <material name="grey">
                <color rgba="0.6 0.6 0.6 1"/>
            </material>
        </visual>
        <collision>
            <origin rpy="0 0 0" xyz="0 0 0.05"/>
            <geometry>
                <cylinder length="0.1" radius="0.03"/>
            </geometry>
        </collision>
    </link>
    
    <!-- Fixed joint attaching the gripper to parent (tool0) -->
    <joint name="gripper_mount_joint" type="fixed">
        <parent link="tool0"/>
        <child link="gripper_base"/>
        <origin rpy="0 0 0" xyz="0 0 0"/>
    </joint>

    <!-- Import control_xacro for Isaac -->
    <xacro:include filename="ur10.ros2_control.xacro" />
    <xacro:ur10_ros2_control name="FakeSystem" initial_positions_file="$(arg initial_positions_file)" ros2_control_hardware_type="$(arg ros2_control_hardware_type)"/>

</robot>